<?xml version="1.0" ?>

<robot name="robot" xmlns:xacro="http://www.ros.org/wiki/xacro">

    <gazebo reference="base_link">
        <material>Gazebo/Black</material>
    </gazebo>
    <gazebo reference="link_front_laser">
        <material>Gazebo/Blue</material>
    </gazebo>
    <gazebo reference="link_left_wheel">
        <material>Gazebo/Blue</material>
    </gazebo>
    <gazebo reference="link_right_wheel">
        <material>Gazebo/Blue</material>
    </gazebo>

    <!-- Parameters definition -->
    <xacro:property name="base_mass" value="20.5" />
    <xacro:property name="pi" value="3.14159265358979323846"/>
    <xacro:property name="vert_kaki" value = "0.349 0.439 0.361 0.75"/>    

    <!-- Link - base_footprint -->
    <link name="base_footprint">
    </link>

    <!-- Joint - base_footprint / base_link -->
    <joint name="joint_base_link" type="fixed">
        <origin rpy="0 0 0" xyz="0 0 0.15" />
        <parent link="base_footprint" />
        <child link="base_link" />
    </joint>

    <!-- Link - base_link -->
    <link name="base_link">
        <inertial>
            <mass value="${base_mass}" />
            <origin xyz="0 0 0" rpy="0 0 0" />
            <inertia ixx="0.47406249999999994" ixy="0.0" ixz="0.0" iyy="0.47406249999999994" iyz="0.0" izz="0.640625" />
        </inertial>

        <collision>
            <origin xyz="0 0 0" rpy="0 0 0" />
            <geometry>
                <cylinder radius="0.25" length="0.30"/>
            </geometry>
        </collision>

        <visual>
            <origin xyz="0 0 0" rpy="0 0 0" />
            <geometry>
                <cylinder radius="0.25" length="0.30"/>
            </geometry>
            <material name="vert_kaki">
                <color rgba="0.349 0.439 0.361 0.75" />
            </material>
        </visual>
    </link>

    <!-- Joint - base_link / left_wheel -->
    <joint name="joint_base_left_wheel" type="continuous">
        <axis rpy="0 0 0" xyz="0 1 0" />
        <origin rpy="0 0 0" xyz="0 0.2 -0.15" />
        <child link="link_left_wheel" />
        <parent link="base_link" />
    </joint>

    <!-- Link left_wheel -->
    <link name="link_left_wheel">
        <inertial>
            <mass value="1"/>
            <origin xyz="0 0 0" rpy="0 0 0" />
            <inertia ixx="0.00034687500000000007" ixy="0.0" ixz="0.0" iyy="0.00034687500000000007" iyz="0.0" izz="0.0004687500000000001" />
        </inertial>

        <collision>
            <origin xyz="0 0 0" rpy="${pi/2} 0 0" />
            <geometry>
                <cylinder radius="0.025" length="0.08"/>
            </geometry>
        </collision>

        <visual>
            <origin xyz="0 0 0" rpy="${pi/2} 0 0" />
            <geometry>
                <cylinder radius="0.025" length="0.08"/>
            </geometry>
            <material name="rouge">
                <color rgba="1 0 0 1" />
            </material>
        </visual>
    </link>

    <!-- Joint - base_link / right_wheel -->
    <joint name="joint_base_right_wheel" type="continuous">
        <axis rpy="0 0 0" xyz="0 1 0" />
        <origin rpy="0 0 0" xyz="0 -0.20 -0.15" />
        <child link="link_right_wheel" />
        <parent link="base_link" />
    </joint>

    <!-- Link right_wheel -->
    <link name="link_right_wheel">
        <inertial>
            <mass value="1"/>
            <origin xyz="0 0 0" rpy="0 0 0" />
            <inertia ixx="0.00034687500000000007" ixy="0.0" ixz="0.0" iyy="0.00034687500000000007" iyz="0.0" izz="0.0004687500000000001" />
        </inertial>

        <collision>
            <origin xyz="0 0 0" rpy="${pi/2} 0 0" />
            <geometry>
                <cylinder radius="0.025" length="0.08"/>
            </geometry>
        </collision>

        <visual>
            <origin xyz="0 0 0" rpy="${pi/2} 0 0" />
            <geometry>
                <cylinder radius="0.025" length="0.08"/>
            </geometry>
            <material name="rouge">
                <color rgba="1 0 0 1" />
            </material>
        </visual>
    </link>

    <!-- Joint - base_link / front_caster_wheel -->
    <joint name="joint_front_caster_wheel" type="fixed">
        <origin rpy="0 0 0" xyz="0.1 0.0 -0.15" />
        <parent link="base_link" />
        <child link="link_front_caster_wheel" />
    </joint>

    <!-- Link front_caster_wheel -->
    <link name="link_front_caster_wheel">
        <inertial>
            <mass value="0.5"/>
            <origin xyz="0 0 0" rpy="0 0 0" />
            <inertia ixx="0.00012500000000000003" ixy="0.0" ixz="0.0" iyy="0.00012500000000000003" iyz="0.0" izz="0.00012500000000000003" />
        </inertial>

        <collision>
            <origin xyz="0 0 0" rpy="0 0 0" />
            <contact_coefficients mu="0.0" kp="0.0" kd="0.0" /> 
            <geometry>
                <sphere radius="0.025"/>
            </geometry>
        </collision>

        <visual>
            <origin xyz="0 0 0" rpy="0 0 0" />
            <geometry>
                <sphere radius="0.025"/>
            </geometry>
            <material name="purple">
                <color rgba="1 0 1 1" />
            </material>
        </visual>
    </link>

    <!-- Joint - base_link / back_caster_wheel -->
    <joint name="joint_back_caster_wheel" type="fixed">
        <origin rpy="0 0 0" xyz="-0.1 0 -0.15" />
        <parent link="base_link" />
        <child link="link_back_caster_wheel" />
    </joint>

    <!-- Link back_caster_wheel -->
    <link name="link_back_caster_wheel">
        <inertial>
            <mass value="0.5"/>
            <origin xyz="0 0 0" rpy="0 0 0" />
            <inertia ixx="0.00012500000000000003" ixy="0.0" ixz="0.0" iyy="0.00012500000000000003" iyz="0.0" izz="0.00012500000000000003" />
        </inertial>

        <collision>
            <origin xyz="0 0 0" rpy="0 0 0" />
            <geometry>
                <sphere radius="0.025"/>
            </geometry>
        </collision>

        <visual>
            <origin xyz="0 0 0" rpy="0 0 0" />
            <geometry>
                <sphere radius="0.025"/>
            </geometry>
            <material name="purple">
                <color rgba="1 0 1 1" />
            </material>
        </visual>
    </link>

    <!-- Joint - base_link / front_laser -->
    <joint name="joint_base_front_laser" type="fixed">
        <origin rpy="${pi} 0 0" xyz="0.25 0.0 0.075" />
        <parent link="base_link" />
        <child link="link_front_laser" />
    </joint>

    <!-- Link front_laser -->
    <link name="link_front_laser">
    </link>

    <!-- Gazebo friction and material properties for left_wheel -->
    <gazebo reference="link_left_wheel">
        <mu1 value="5.0"/>
		<mu2 value="0.5"/>
		<kp value="10000000.0" />
		<kd value="1.0" />
		<fdir1 value="1 0 0"/>
    </gazebo>

    <!-- Gazebo friction and material properties for right_wheel -->
    <gazebo reference="link_right_wheel">
        <mu1 value="5.0"/>
		<mu2 value="0.5"/>
		<kp value="10000000.0" />
		<kd value="1.0" />
		<fdir1 value="1 0 0"/>
    </gazebo>

    <!-- Gazebo friction and material properties for front_caster -->
    <gazebo reference="link_front_caster_wheel">
        <mu1 value="0.0"/>
        <mu2 value="0.0"/>
        <kp value="10000000.0" />
        <kd value="100.0" />
        <fdir1 value="0 0 1"/>
        <material>Gazebo/Gray</material>
    </gazebo>

    <!-- Gazebo friction and material properties for back_caster -->
    <gazebo reference="link_back_caster_wheel">
        <mu1 value="0.0"/>
        <mu2 value="0.0"/>
        <kp value="10000000.0" />
        <kd value="100.0" />
        <fdir1 value="0 0 1"/>
        <material>Gazebo/Gray</material>
    </gazebo>

    <!-- Gazebo plugin for Differential drive controller -->
    <gazebo>
        <plugin filename="libgazebo_ros_diff_drive.so" name="differential_drive_controller">
            <alwaysOn>true</alwaysOn>
            <updateRate>20</updateRate>
            <leftJoint>joint_base_left_wheel</leftJoint>
            <rightJoint>joint_base_right_wheel</rightJoint>
            <publishWheelTF>true</publishWheelTF>
            <wheelSeparation>0.4</wheelSeparation>
            <wheelDiameter>0.05</wheelDiameter>
            <torque>10</torque>
            <commandTopic>cmd_vel</commandTopic>
            <odometryTopic>odom</odometryTopic>
            <odometryFrame>odom</odometryFrame>
            <robotBaseFrame>base_footprint</robotBaseFrame>
        </plugin>
    </gazebo>

    <!-- Gazebo configuration for the front laser sensor -->
    <gazebo reference="link_front_laser">
        <sensor type="ray" name="head_hokuyo_sensor">
            <pose>0 0 0 0 0 0</pose>
            <visualize>true</visualize>
            <update_rate>20</update_rate>
            <ray>
                <scan>
                    <horizontal>
                        <samples>720</samples>
                        <resolution>1</resolution>
                        <min_angle>-1.570796</min_angle>
                        <max_angle>1.570796</max_angle>
                    </horizontal>
                </scan>
                <!-- Configure the range properties -->
                <range>
                    <min>0.1</min>
                    <max>10.0</max>
                    <resolution>0.01</resolution>
                </range>
                <!-- Configure the noise properties -->
                <noise>
                    <type>gaussian</type>
                    <mean>0.0</mean>
                    <stddev>0.01</stddev>
                </noise>
            </ray>
            <!-- Attach a Gazebo plugin to the sensor for ROS integration -->
            <plugin name="gazebo_ros_head_hokuyo_controller" filename="libgazebo_ros_laser.so">
                <topicName>/scan</topicName>
                <frameName>sensor_laser</frameName>
            </plugin>
        </sensor>
    </gazebo>
</robot>